<?xml version="1.0" ?>
<!-- =================================================================================== -->
<!-- |    This document was autogenerated by xacro from /home/fan/catkin_ws/src/qkm_description/urdf/qkm_urdf.xacro | -->
<!-- |    EDITING THIS FILE BY HAND IS NOT RECOMMENDED                                 | -->
<!-- =================================================================================== -->
<robot name="qkm">
    <material name="black">
        <color rgba="0.0 0.0 0.0 1.0" />
    </material>
    <material name="blue">
        <color rgba="0.0 0.0 0.8 1.0" />
    </material>
    <material name="green">
        <color rgba="0.0 0.8 0.0 1.0" />
    </material>
    <material name="gray">
        <color rgba="0.2 0.2 0.2 1.0" />
    </material>
    <material name="light_gray">
        <color rgba="0.4 0.4 0.4 1.0" />
    </material>
    <material name="orange">
        <color rgba="1.0 0.423529411765 0.0392156862745 1.0" />
    </material>
    <material name="brown">
        <color rgba="0.870588235294 0.811764705882 0.764705882353 1.0" />
    </material>
    <material name="red">
        <color rgba="0.8 0.0 0.0 1.0" />
    </material>
    <material name="white">
        <color rgba="1.0 1.0 1.0 1.0" />
    </material>
    <material name="qkm_red">
        <color rgba="0.698039215686 0.133333333333 0.133333333333 1.0" />
    </material>
    <gazebo>
        <plugin filename="libgazebo_ros_control.so" name="ros_control">
            <!--robotNamespace>/</robotNamespace-->
            <!--robotSimType>gazebo_ros_control/DefaultRobotHWSim</robotSimType-->
        </plugin>
    </gazebo>
    <!--
  Author: Kelsey Hawkins
  Contributers: Jimmy Da Silva, Ajit Krisshna N L, Muhammad Asif Rana
-->
    <!-- Kinematic model -->
    <link name="base_link">
        <visual>
            <geometry>
                <mesh filename="package://qkm_description/meshes/base.stl" />
            </geometry>
            <origin rpy="0.0 0.0 0.0" xyz="0.0 0.0 0.0" />
            <material name="light_gray" />
        </visual>
        <collision>
            <geometry>
                <mesh filename="package://qkm_description/meshes/base.stl" />
            </geometry>
            <origin rpy="0.0 0.0 0.0" xyz="0.0 0.0 0.0" />
        </collision>
        
<inertial>
            <mass value="4.0" />
            <origin rpy="0.0 0.0 0.0" xyz="0.0 0.0 0.0" />
            <inertia ixx="0.0061063308908" ixy="0.0" ixz="0.0" iyy="0.0061063308908" iyz="0.0" izz="0.01125" />
        </inertial>

    </link>
    <joint name="shoulder_pan_joint" type="revolute">
        <parent link="base_link" />
        <child link="shoulder_link" />
        <origin rpy="0 0 0" xyz="0 0 0.1195" />
        <axis xyz="0 0 1" />
        <limit effort="330.0" lower="-3.141592653589793" upper="3.141592653589793" velocity="2.16" />
        <dynamics damping="0.0" friction="0.0" />
    </joint>
    <link name="shoulder_link">
        <visual>
            <geometry>
                <mesh filename="package://qkm_description/meshes/shoulder.stl" />
            </geometry>
            <origin rpy="0.0 0.0 0.0" xyz="0.0 0.0 0.0" />
            <material name="qkm_red" />
        </visual>
        <collision>
            <geometry>
                <mesh filename="package://qkm_description/meshes/shoulder.stl" />
            </geometry>
            <origin rpy="0.0 0.0 0.0" xyz="0.0 0.0 0.0" />
        </collision>

<inertial>
            <origin rpy="0 0 0" xyz="0.021 -0.027 0.000" />
            <mass value="7.1" />
            <inertia ixx="0.03408" ixy="-0.00425" ixz="0.00002" iyy="0.02156" iyz="0.00008" izz="0.03529" />
        </inertial>

    </link>
    <joint name="shoulder_lift_joint" type="revolute">
        <parent link="shoulder_link" />
        <child link="upper_arm_link" />
        <origin rpy="1.570796327 0 0" xyz="0 0 0" />
        <axis xyz="0 0 1" />
        <limit effort="330.0" lower="-3.141592653589793" upper="0.17453292519943295" velocity="2.16" />
        <dynamics damping="0.0" friction="0.0" />
    </joint>
    <link name="upper_arm_link">
        <visual>
            <geometry>
                <mesh filename="package://qkm_description/meshes/upperarm.stl" />
            </geometry>
            <origin rpy="0.0 0.0 0.0" xyz="0.0 0.0 0.0" />
            <material name="qkm_red" />
        </visual>
        <collision>
            <geometry>
                <mesh filename="package://qkm_description/meshes/upperarm.stl" />
            </geometry>
            <origin rpy="0.0 0.0 0.0" xyz="0.0 0.0 0.0" />
        </collision>

<inertial>
            <origin rpy="0 0 0" xyz="-0.232 0.000 0.158" />
            <mass value="12.7" />
            <inertia ixx="0.02814" ixy="0.00005" ixz="-0.01561" iyy="0.77068" iyz="0.00002" izz="0.76943" />
        </inertial>

    </link>
    <joint name="elbow_joint" type="revolute">
        <parent link="upper_arm_link" />
        <child link="forearm_link" />
        <origin rpy="0 0 0" xyz="-0.45 0 0" />
        <axis xyz="0 0 1" />
        <limit effort="150.0" lower="-2.6179938779914944" upper="2.6179938779914944" velocity="3.15" />
        <dynamics damping="0.0" friction="0.0" />
    </joint>
    <link name="forearm_link">
        <visual>
            <geometry>
                <mesh filename="package://qkm_description/meshes/forearm.stl" />
            </geometry>
            <origin rpy="0.0 0.0 0.0" xyz="0.0 0.0 0.0" />
            <material name="qkm_red" />
        </visual>
        <collision>
            <geometry>
                <mesh filename="package://qkm_description/meshes/forearm.stl" />
            </geometry>
            <origin rpy="0.0 0.0 0.0" xyz="0.0 0.0 0.0" />
        </collision>

<inertial>
            <origin rpy="0 0 0" xyz="-0.3323 0.000 0.068" />
            <mass value="4.27" />
            <inertia ixx="0.01014" ixy="0.00008" ixz="0.00916" iyy="0.30928" iyz="0.00000" izz="0.30646" />
        </inertial>

    </link>
    <joint name="wrist_1_joint" type="revolute">
        <parent link="forearm_link" />
        <child link="wrist_1_link" />
        <origin rpy="0 0 0" xyz="-0.3975 0 0.1465" />
        <axis xyz="0 0 1" />
        <limit effort="54.0" lower="-3.14159" upper="3.14159" velocity="3.2" />
        <dynamics damping="0.0" friction="0.0" />
    </joint>
    <link name="wrist_1_link">
        <visual>
            <geometry>
                <mesh filename="package://qkm_description/meshes/wrist1.stl" />
            </geometry>
            <origin rpy="0.0 0.0 3.141592653589793" xyz="0.0 0.0 0.0" />
            <material name="qkm_red" />
        </visual>
        <collision>
            <geometry>
                <mesh filename="package://qkm_description/meshes/wrist1.stl" />
            </geometry>
            <origin rpy="0.0 0.0 0.0" xyz="0.0 0.0 0.0" />
        </collision>

<inertial>
            <origin rpy="0 0 0" xyz="0.000 -0.018 0.007" />
            <mass value="2.000" />
            <inertia ixx="0.00296" ixy="-0.00000" ixz="-0.00001" iyy="0.00258" iyz="-0.00024" izz="0.00222" />
        </inertial>

    </link>
    <joint name="wrist_2_joint" type="revolute">
        <parent link="wrist_1_link" />
        <child link="wrist_2_link" />
        <origin rpy="1.570796327 0 0" xyz="0 -0.1145 0" />
        <axis xyz="0 0 1" />
        <limit effort="54.0" lower="-3.14159" upper="3.14159" velocity="3.2" />
        <dynamics damping="0.0" friction="0.0" />
    </joint>
    <link name="wrist_2_link">
        <visual>
            <geometry>
                <mesh filename="package://qkm_description/meshes/wrist2.stl" />
            </geometry>
            <origin rpy="0.0 0.0 0.0" xyz="0.0 0.0 0.0" />
            <material name="qkm_red" />
        </visual>
        <collision>
            <geometry>
                <mesh filename="package://qkm_description/meshes/wrist2.stl" />
            </geometry>
            <origin rpy="0.0 0.0 0.0" xyz="0.0 0.0 0.0" />
        </collision>

<inertial>
            <origin rpy="0 0 0" xyz="0.000 0.018 -0.007" />
            <mass value="2.000" />
            <inertia ixx="0.00296" ixy="-0.00000" ixz="-0.00001" iyy="0.00258" iyz="-0.00024" izz="0.00222" />
        </inertial>

    </link>
    <joint name="wrist_3_joint" type="revolute">
        <parent link="wrist_2_link" />
        <child link="wrist_3_link" />
        <origin rpy="1.570796326589793 3.141592653589793 3.141592653589793" xyz="0 0.0985 0" />
        <axis xyz="0 0 1" />
        <limit effort="54.0" lower="-3.14159" upper="3.14159" velocity="3.2" />
        <dynamics damping="0.0" friction="0.0" />
    </joint>
    <link name="wrist_3_link">
        <visual>
            <geometry>
                <mesh filename="package://qkm_description/meshes/wrist3.stl" />
            </geometry>
            <origin rpy="0 0 0" xyz="0.0 0.0 0.0" />
            <material name="LightGrey">
                <color rgba="0.7 0.7 0.7 1.0" />
            </material>
        </visual>
        <collision>
            <geometry>
                <mesh filename="package://qkm_description/meshes/wrist3.stl" />
            </geometry>
            <origin rpy="0 0 0" xyz="0.0 0.0 0.0" />
        </collision>

<inertial>
            <origin rpy="0 0 0" xyz="0 0 -0.026" />
            <mass value="0.365" />
            <inertia ixx="0.00040" ixy="0.00000" ixz="-0.00000" iyy="0.00041" iyz="0.00000" izz="0.00034" />
        </inertial>

    </link>
    <!-- tool -->
    <!--joint name="${prefix}tool_joint" type="fixed">
      <parent link="${prefix}wrist_3_link" />
      <child link = "${prefix}tool_link" />
      <origin xyz="0.0 0.0 0.0" rpy="0.0 0.0 0.0" />
    </joint>

    <link name="${prefix}tool_link">
      <visual>
        <geometry>
          <mesh filename="package://qkm_description/meshes/tool.stl"/>
        </geometry>
        <origin xyz="0.0 0.0 0.0" rpy="0.0 0.0 0.0"/>
        <material name="LightGrey">
          <color rgba="0.7 0.7 0.7 1.0"/>
        </material>
      </visual>
      <collision>
        <geometry>
          <mesh filename="package://qkm_description/meshes/tool.stl"/>
        </geometry>
         <origin xyz="0.0 0.0 0.0" rpy="0.0 0.0 0.0" />
      </collision>
      <xacro:cylinder_inertial radius="0.05" length="0.95" mass="2.4">
        <origin xyz="0.06 0.17 0.0" rpy="0.0 0.0 0.0" />
      </xacro:cylinder_inertial>
    </link>

    <joint name="${prefix}ee_fixed_joint" type="fixed">
      <parent link="${prefix}tool_link" />
      <child link = "${prefix}ee_link" />
      <origin xyz="0.0 ${__kinematics['tool_length']} 0.0" rpy="0.0 0.0 0.0" />
    </joint>

    <link name="${prefix}ee_link">
      <collision>
        <geometry>
          <box size="0.001 0.001 0.001"/>
        </geometry>
        <origin rpy="0 0 0" xyz="-0.001 0 0"/>
      </collision>
    </link-->

<transmission name="shoulder_pan_trans">
        <type>transmission_interface/SimpleTransmission</type>
        <joint name="shoulder_pan_joint">
            <hardwareInterface>hardware_interface/PositionJointInterface</hardwareInterface>
        </joint>
        <actuator name="shoulder_pan_motor">
            <mechanicalReduction>1</mechanicalReduction>
        </actuator>
    </transmission>
    <transmission name="shoulder_lift_trans">
        <type>transmission_interface/SimpleTransmission</type>
        <joint name="shoulder_lift_joint">
            <hardwareInterface>hardware_interface/PositionJointInterface</hardwareInterface>
        </joint>
        <actuator name="shoulder_lift_motor">
            <mechanicalReduction>1</mechanicalReduction>
        </actuator>
    </transmission>
    <transmission name="elbow_trans">
        <type>transmission_interface/SimpleTransmission</type>
        <joint name="elbow_joint">
            <hardwareInterface>hardware_interface/PositionJointInterface</hardwareInterface>
        </joint>
        <actuator name="elbow_motor">
            <mechanicalReduction>1</mechanicalReduction>
        </actuator>
    </transmission>
    <transmission name="wrist_1_trans">
        <type>transmission_interface/SimpleTransmission</type>
        <joint name="wrist_1_joint">
            <hardwareInterface>hardware_interface/PositionJointInterface</hardwareInterface>
        </joint>
        <actuator name="wrist_1_motor">
            <mechanicalReduction>1</mechanicalReduction>
        </actuator>
    </transmission>
    <transmission name="wrist_2_trans">
        <type>transmission_interface/SimpleTransmission</type>
        <joint name="wrist_2_joint">
            <hardwareInterface>hardware_interface/PositionJointInterface</hardwareInterface>
        </joint>
        <actuator name="wrist_2_motor">
            <mechanicalReduction>1</mechanicalReduction>
        </actuator>
    </transmission>
    <transmission name="wrist_3_trans">
        <type>transmission_interface/SimpleTransmission</type>
        <joint name="wrist_3_joint">
            <hardwareInterface>hardware_interface/PositionJointInterface</hardwareInterface>
        </joint>
        <actuator name="wrist_3_motor">
            <mechanicalReduction>1</mechanicalReduction>
        </actuator>
    </transmission>
    <gazebo reference="base_link">
        <selfCollide>true</selfCollide>
    </gazebo>
    <gazebo reference="shoulder_link">
        <selfCollide>true</selfCollide>
    </gazebo>
    <gazebo reference="upper_arm_link">
        <selfCollide>true</selfCollide>
    </gazebo>
    <gazebo reference="forearm_link">
        <selfCollide>true</selfCollide>
    </gazebo>
    <gazebo reference="wrist_1_link">
        <selfCollide>true</selfCollide>
    </gazebo>
    <gazebo reference="wrist_3_link">
        <selfCollide>true</selfCollide>
    </gazebo>
    <gazebo reference="wrist_2_link">
        <selfCollide>true</selfCollide>
    </gazebo>
    <gazebo reference="ee_link">
        <selfCollide>true</selfCollide>
    </gazebo>
    <!-- Frame coincident with all-zeros TCP on UR controller -->
    <!--link name="${prefix}tool0_controller"/>
    <joint name="${prefix}wrist_3_link-tool0_fixed_joint" type="fixed">
      <origin xyz="0 0 0" rpy="0 0 0"/>
      <parent link="${prefix}wrist_3_link"/>
      <child link="${prefix}tool0_controller"/>
    </joint-->
    <link name="world" />
    <!-- place table -->
    <joint name="world_joint" type="fixed">
        <parent link="world" />
        <child link="base_link" />
        <origin rpy="0.0 0.0 0.0" xyz="0.0 0.0 0.0" />
    </joint>
    <transmission name="trans_shoulder_pan_joint">
        <type>transmission_interface/SimpleTransmission</type>
        <joint name="shoulder_pan_joint">
            <hardwareInterface>hardware_interface/EffortJointInterface</hardwareInterface>
        </joint>
        <actuator name="shoulder_pan_joint_motor">
            <hardwareInterface>hardware_interface/EffortJointInterface</hardwareInterface>
            <mechanicalReduction>1</mechanicalReduction>
        </actuator>
    </transmission>
    <transmission name="trans_shoulder_lift_joint">
        <type>transmission_interface/SimpleTransmission</type>
        <joint name="shoulder_lift_joint">
            <hardwareInterface>hardware_interface/EffortJointInterface</hardwareInterface>
        </joint>
        <actuator name="shoulder_lift_joint_motor">
            <hardwareInterface>hardware_interface/EffortJointInterface</hardwareInterface>
            <mechanicalReduction>1</mechanicalReduction>
        </actuator>
    </transmission>
    <transmission name="trans_elbow_joint">
        <type>transmission_interface/SimpleTransmission</type>
        <joint name="elbow_joint">
            <hardwareInterface>hardware_interface/EffortJointInterface</hardwareInterface>
        </joint>
        <actuator name="elbow_joint_motor">
            <hardwareInterface>hardware_interface/EffortJointInterface</hardwareInterface>
            <mechanicalReduction>1</mechanicalReduction>
        </actuator>
    </transmission>
    <transmission name="trans_wrist_1_joint">
        <type>transmission_interface/SimpleTransmission</type>
        <joint name="wrist_1_joint">
            <hardwareInterface>hardware_interface/EffortJointInterface</hardwareInterface>
        </joint>
        <actuator name="wrist_1_joint_motor">
            <hardwareInterface>hardware_interface/EffortJointInterface</hardwareInterface>
            <mechanicalReduction>1</mechanicalReduction>
        </actuator>
    </transmission>
    <transmission name="trans_wrist_2_joint">
        <type>transmission_interface/SimpleTransmission</type>
        <joint name="wrist_2_joint">
            <hardwareInterface>hardware_interface/EffortJointInterface</hardwareInterface>
        </joint>
        <actuator name="wrist_2_joint_motor">
            <hardwareInterface>hardware_interface/EffortJointInterface</hardwareInterface>
            <mechanicalReduction>1</mechanicalReduction>
        </actuator>
    </transmission>
    <transmission name="trans_wrist_3_joint">
        <type>transmission_interface/SimpleTransmission</type>
        <joint name="wrist_3_joint">
            <hardwareInterface>hardware_interface/EffortJointInterface</hardwareInterface>
        </joint>
        <actuator name="wrist_3_joint_motor">
            <hardwareInterface>hardware_interface/EffortJointInterface</hardwareInterface>
            <mechanicalReduction>1</mechanicalReduction>
        </actuator>
    </transmission>
    <gazebo>
        <plugin name="gazebo_ros_control" filename="libgazebo_ros_control.so">
            <robotNamespace>/</robotNamespace>
        </plugin>
    </gazebo>
</robot>
